<?xml version="1.0"?>
<robot name="my_robot">

    <!-- grey colour -->
    <material name="grey">
        <color rgba="0.7 0.7 0.7 1" />
    </material>

    <!-- green colour -->
    <material name="green">
        <color rgba="0 0.6 0 1" />
    </material>

    <!-- white colour -->
    <material name="white">
        <color rgba="1 1 1 1" />
    </material>


<!-- Links -->

    <!-- base footprint link -->
    <link name="base_footprint_link" />

    <!-- base link -->
    <link name="base_link">
        <visual>
            <geometry>
                <box size="0.6 0.4 0.2" />
            </geometry>
            <!-- offset origin to be at the bottom -->
            <origin xyz="0 0 0.1" rpy="0 0 0" />

            <material name="green" />
        </visual>
    </link>

    <!-- lidar link -->
    <link name="lidar_link">
        <visual>
            <geometry>
                <cylinder radius="0.1" length="0.05" />
            </geometry>

            <origin xyz="0 0 0" rpy="0 0 0" />
            <material name="white" />

        </visual>
    </link>

    <!-- Left wheel link -->
    <link name="left_wheel_link">
        <visual>
            <geometry>
                <cylinder radius="0.1" length="0.05" />
            </geometry>
            <!-- use radians -->
            <origin xyz="0 0 0" rpy="${pi/2} 0 0" />
            <material name="grey" />

        </visual>
    </link>        

    <!-- Right wheel link -->
    <link name="right_wheel_link">
        <visual>
            <geometry>
                <cylinder radius="0.1" length="0.05" />
            </geometry>

            <origin xyz="0 0 0" rpy="${pi/2} 0 0" />
            <material name="grey" />
        </visual>
    </link>        

    <!-- Caster wheel link -->
    <link name="caster_wheel_link">
        <visual>
            <geometry>
                <sphere radius="0.05" />
            </geometry>

            <origin xyz="0 0 0" rpy="0 0 0" />
            <material name="grey" />
        </visual>

    </link>


<!-- Joints -->
    <!-- Base footprint - base joint -->
    <joint name="base_joint" type="fixed">
        <parent link="base_footprint_link" />
        <child link="base_link" />
        <origin xyz="0 0 0.1" rpy="0 0 0" />
    </joint>

    <!-- Base - lidar joint -->
    <joint name="base_lidar_joint" type="fixed">
        <parent link="base_link" />
        <child link="lidar_link" />
        <origin xyz="0 0 0.225" rpy="0 0 0" />
    </joint>

    <!-- Base - left wheel link -->
    <joint name="base_left_wheel_joint" type="continuous">
        <parent link="base_link" />
        <child link="left_wheel_link" />
        <origin xyz="-0.15 0.225 0" rpy="0 0 0" />
        <axis xyz="0 1 0" />
    </joint>

    <!-- Base - right wheel joint -->
    <joint name="base_right_wheel_joint" type="continuous">
        <parent link="base_link" />
        <child link="right_wheel_link" />
        <origin xyz="-0.15 -0.225 0" rpy="0 0 0" />
        <axis xyz="0 1 0" />
    </joint>

    <!-- Base - caster wheel joint -->
    <joint name="base_caster_wheel_joint" type="fixed">
        <parent link="base_link" />
        <child link="caster_wheel_link" />
        <origin xyz="0.15 0 -0.05" rpy="0 0 0" />
    </joint>

</robot>